Workbook

Sheet Calculator
A1: Stroke Neuroprotection Deliverability (Reachability) Calculator
A2: Imaging-driven upper-bound screen for whether a systemically administered drug can plausibly reach the lesion centre.
A4: Inputs
A5: Drug | B5: MgSO4 | C5: Select base drug.
A6: Parameter scenario | B6: Mid-case | C6: Mid-case = D_mid/k_mid; Conservative = D_low/k_high; Permissive = D_high/k_low.
A7: Geometry | B7: Slab | C7: Distance input is always centre-to-rim distance d.
A8: Core volume V (mL) | B8: 65 | C8: Enter baseline core volume from CTP/DWI, or leave blank and use d.
A9: Override centre-to-rim distance d (mm) | C9: Optional manual override of d (mm).
A10: Active distance d (mm) | B10: =IF(B9<>"",B9,IF(B8<>"",(3*B8*1000/(4*PI()))^(1/3),"")) -> 24.942592 | C10: If B9 is blank, d is derived from core volume.
A11: Threshold M (fraction of boundary) | B11: 0.01 | C11: Examples: 0.01 = 1%; 0.10 = 10%.
A12: Library key | B12: =B5&" | "&B6 -> MgSO4 | Mid-case
A13: Library D (µm²/s) | B13: =VLOOKUP(B12,DrugParams!$A$2:$F$19,4,FALSE) -> 387.28
A14: Library k (1/s) | B14: =VLOOKUP(B12,DrugParams!$A$2:$F$19,5,FALSE) -> 3.703e-05
A15: Optional custom D override | C15: Leave blank to use library D.
A16: Optional custom k override | C16: Leave blank to use library k.
A17: Active D (µm²/s) | B17: =IF(B15="",B13,B15) -> 387.28 | C17: Active values drive all steady-state outputs.
A18: Active k (1/s) | B18: =IF(B16="",B14,B16) -> 3.703e-05
A20: Outputs
A21: Penetration length λ (mm) | B21: =SQRT((B17/1000000)/B18) -> 3.2339677
A22: Consumption half-life ln(2)/k (h) | B22: =LN(2)/B18/3600 -> 5.1995918
A23: Steady-state centre level (% of boundary) | B23: =IF(B7="Slab",100/COSH(B10/B21),IF(B7="Cylinder",100/BESSELI(B10/B21,0),100*(B10/B21)/SINH(B10/B21))) -> 0.089423361
A24: Reachable at threshold M? | B24: =IF(B23/100>=B11,"Reachable","NR (Css<M)") -> NR (Css<M) | C24: Green = reachable; red = NR.
A25: Critical distance d_crit(M) (mm) | B25: =B21*ACOSH(1/B11) -> 17.134506
A26: Equivalent sphere V_crit(M) (mL) | B26: =4*PI()/3*POWER(B25,3)/1000 -> 21.071886
A27: k_crit(d,M) for slab (1/s) | B27: =IF(B7<>"Slab","(slab only)",(B17/1000000)/POWER((B10/ACOSH(1/B11)),2)) -> 1.7474862e-05
A28: k / k_crit margin (slab only) | B28: =IF(B7<>"Slab","(slab only)",B18/B27) -> 2.119044
A29: Interpretation | B29: =IF(B7<>"Slab","Use steady-state % + d_crit for non-slab geometries",IF(B28<=1,"Reachable at steady state","NR at steady state")) -> NR at steady state | C29: Interpretation is based on the slab reachability boundary.
A31: Standard clinical distances (library parameter sets)
A32: L (cm) | B32: d (mm) | C32: Steady-state % | D32: Reach @1% | E32: Reach @10% | F32: t₁% (h) | G32: t₁₀% (h)
A33: 1 | B33: =A33*5 -> 5 | C33: =IF(B7="Slab",100/COSH(B33/B21),IF(B7="Cylinder",100/BESSELI(B33/B21,0),100*(B33/B21)/SINH(B33/B21))) -> 40.765107 | D33: =IF(C33>=1,"Reachable","NR") -> Reachable | E33: =IF(C33>=10,"Reachable","NR") -> Reachable | F33: =IF(COUNTA($B$15:$B$16)>0,"Use Python",VLOOKUP($B$12&" | L="&A33&" cm",ClinicalLookup!$A$2:$J$55,8,FALSE)) -> 1.1729016 | G33: =IF(COUNTA($B$15:$B$16)>0,"Use Python",VLOOKUP($B$12&" | L="&A33&" cm",ClinicalLookup!$A$2:$J$55,10,FALSE)) -> 2.6180815
A34: 2 | B34: =A34*5 -> 10 | C34: =IF(B7="Slab",100/COSH(B34/B21),IF(B7="Cylinder",100/BESSELI(B34/B21,0),100*(B34/B21)/SINH(B34/B21))) -> 9.0619219 | D34: =IF(C34>=1,"Reachable","NR") -> Reachable | E34: =IF(C34>=10,"Reachable","NR") -> NR | F34: =IF(COUNTA($B$15:$B$16)>0,"Use Python",VLOOKUP($B$12&" | L="&A34&" cm",ClinicalLookup!$A$2:$J$55,8,FALSE)) -> 5.2257932 | G34: =IF(COUNTA($B$15:$B$16)>0,"Use Python",VLOOKUP($B$12&" | L="&A34&" cm",ClinicalLookup!$A$2:$J$55,10,FALSE)) -> 0
A35: 5 | B35: =A35*5 -> 25 | C35: =IF(B7="Slab",100/COSH(B35/B21),IF(B7="Cylinder",100/BESSELI(B35/B21,0),100*(B35/B21)/SINH(B35/B21))) -> 0.087849962 | D35: =IF(C35>=1,"Reachable","NR") -> NR | E35: =IF(C35>=10,"Reachable","NR") -> NR | F35: =IF(COUNTA($B$15:$B$16)>0,"Use Python",VLOOKUP($B$12&" | L="&A35&" cm",ClinicalLookup!$A$2:$J$55,8,FALSE)) -> 0 | G35: =IF(COUNTA($B$15:$B$16)>0,"Use Python",VLOOKUP($B$12&" | L="&A35&" cm",ClinicalLookup!$A$2:$J$55,10,FALSE)) -> 0
A37: Standard-distance times are precomputed for the library parameter sets. If custom D or k overrides are entered, use the Python calculator for time-to-threshold.

Sheet DrugParams
A1: Key | B1: Drug | C1: Scenario | D1: D (µm²/s) | E1: k (1/s) | F1: Definition
A2: Edaravone | Mid-case | B2: Edaravone | C2: Mid-case | D2: 342.39 | E2: 3.5e-05 | F2: D_mid and k_mid
A3: Edaravone | Conservative | B3: Edaravone | C3: Conservative | D3: 171.19 | E3: 0.00035 | F3: D_low and k_high
A4: Edaravone | Permissive | B4: Edaravone | C4: Permissive | D4: 684.78 | E4: 7.04e-07 | F4: D_high and k_low
A5: Fasudil | Mid-case | B5: Fasudil | C5: Mid-case | D5: 288.44 | E5: 0.000481 | F5: D_mid and k_mid
A6: Fasudil | Conservative | B6: Fasudil | C6: Conservative | D6: 144.22 | E6: 0.00481 | F6: D_low and k_high
A7: Fasudil | Permissive | B7: Fasudil | C7: Permissive | D7: 576.88 | E7: 4.81e-05 | F7: D_high and k_low
A8: MgSO4 | Mid-case | B8: MgSO4 | C8: Mid-case | D8: 387.28 | E8: 3.703e-05 | F8: D_mid and k_mid
A9: MgSO4 | Conservative | B9: MgSO4 | C9: Conservative | D9: 193.64 | E9: 0.0003703 | F9: D_low and k_high
A10: MgSO4 | Permissive | B10: MgSO4 | C10: Permissive | D10: 774.56 | E10: 3.703e-06 | F10: D_high and k_low
A11: Uric Acid | Mid-case | B11: Uric Acid | C11: Mid-case | D11: 346.47 | E11: 0.000144 | F11: D_mid and k_mid
A12: Uric Acid | Conservative | B12: Uric Acid | C12: Conservative | D12: 173.24 | E12: 0.00144 | F12: D_low and k_high
A13: Uric Acid | Permissive | B13: Uric Acid | C13: Permissive | D13: 692.94 | E13: 1.44e-05 | F13: D_high and k_low
... A19: Minocycline | Permissive | B19: Minocycline | C19: Permissive | D19: 496.32 | E19: 8.37e-07 | F19: D_high and k_low

Sheet ClinicalLookup
A1: LookupKey | B1: Drug | C1: Scenario | D1: L_cm | E1: d_mm | F1: Css_% | G1: Reach_1pct | H1: t1%_h | I1: Reach_10pct | J1: t10%_h
A2: Edaravone | Mid-case | L=1 cm | B2: Edaravone | C2: Mid-case | D2: 1 | E2: 5 | F2: 38.847423 | G2: Reachable | H2: 1.3294509 | I2: Reachable | J2: 2.988782
A3: Edaravone | Mid-case | L=2 cm | B3: Edaravone | C3: Mid-case | D3: 2 | E3: 10 | F3: 8.1614419 | G3: Reachable | H3: 5.9804099 | I3: NR
A4: Edaravone | Mid-case | L=5 cm | B4: Edaravone | C4: Mid-case | D4: 5 | E4: 25 | F4: 0.067559235 | G4: NR | I4: NR
A5: Edaravone | Conservative | L=1 cm | B5: Edaravone | C5: Conservative | D5: 1 | E5: 5 | F5: 0.15707925 | G5: NR | I5: NR
A6: Edaravone | Conservative | L=2 cm | B6: Edaravone | C6: Conservative | D6: 2 | E6: 10 | F6: 0.00012336961 | G6: NR | I6: NR
A7: Edaravone | Conservative | L=5 cm | B7: Edaravone | C7: Conservative | D7: 5 | E7: 25 | F7: 5.9768933e-14 | G7: NR | I7: NR
A8: Edaravone | Permissive | L=1 cm | B8: Edaravone | C8: Permissive | D8: 1 | E8: 5 | F8: 98.728535 | G8: Reachable | H8: 0.64378327 | I8: Reachable | J8: 1.321446
A9: Edaravone | Permissive | L=2 cm | B9: Edaravone | C9: Permissive | D9: 2 | E9: 10 | F9: 95.071018 | G9: Reachable | H9: 2.577468 | I9: Reachable | J9: 5.3030127
A10: Edaravone | Permissive | L=5 cm | B10: Edaravone | C10: Permissive | D10: 5 | E10: 25 | F10: 74.691173 | G10: Reachable | H10: 16.216804 | I10: Reachable | J10: 33.934082
A11: Fasudil | Mid-case | L=1 cm | B11: Fasudil | C11: Mid-case | D11: 1 | E11: 5 | F11: 0.31397328 | G11: NR | I11: NR
A12: Fasudil | Mid-case | L=2 cm | B12: Fasudil | C12: Mid-case | D12: 2 | E12: 10 | F12: 0.00049289852 | G12: NR | I12: NR
A13: Fasudil | Mid-case | L=5 cm | B13: Fasudil | C13: Mid-case | D13: 5 | E13: 25 | F13: 1.9069916e-12 | G13: NR | I13: NR
A14: Fasudil | Conservative | L=1 cm | B14: Fasudil | C14: Conservative | D14: 1 | E14: 5 | F14: 5.7617112e-11 | G14: NR | I14: NR
A15: Fasudil | Conservative | L=2 cm | B15: Fasudil | C15: Conservative | D15: 2 | E15: 10 | F15: 1.6598658e-23 | G15: NR | I15: NR
A16: Fasudil | Conservative | L=5 cm | B16: Fasudil | C16: Conservative | D16: 5 | E16: 25 | F16: 3.9686012e-61 | G16: NR | I16: NR
A17: Fasudil | Permissive | L=1 cm | B17: Fasudil | C17: Permissive | D17: 1 | E17: 5 | F17: 44.715741 | G17: Reachable | H17: 0.78420548 | I17: Reachable | J17: 1.7286669
A18: Fasudil | Permissive | L=2 cm | B18: Fasudil | C18: Permissive | D18: 2 | E18: 10 | F18: 11.108009 | G18: Reachable | H18: 3.436534 | I18: Reachable | J18: 14.546596
A19: Fasudil | Permissive | L=5 cm | B19: Fasudil | C19: Permissive | D19: 5 | E19: 25 | F19: 0.14652446 | G19: NR | I19: NR
A20: MgSO4 | Mid-case | L=1 cm | B20: MgSO4 | C20: Mid-case | D20: 1 | E20: 5 | F20: 40.765107 | G20: Reachable | H20: 1.1729016 | I20: Reachable | J20: 2.6180815
A21: MgSO4 | Mid-case | L=2 cm | B21: MgSO4 | C21: Mid-case | D21: 2 | E21: 10 | F21: 9.0619219 | G21: Reachable | H21: 5.2257932 | I21: NR
A22: MgSO4 | Mid-case | L=5 cm | B22: MgSO4 | C22: Mid-case | D22: 5 | E22: 25 | F22: 0.087849962 | G22: NR | I22: NR
A23: MgSO4 | Conservative | L=1 cm | B23: MgSO4 | C23: Conservative | D23: 1 | E23: 5 | F23: 0.19869164 | G23: NR | I23: NR
A24: MgSO4 | Conservative | L=2 cm | B24: MgSO4 | C24: Conservative | D24: 2 | E24: 10 | F24: 0.00019739223 | G24: NR | I24: NR
A25: MgSO4 | Conservative | L=5 cm | B25: MgSO4 | C25: Conservative | D25: 5 | E25: 25 | F25: 1.9354419e-13 | G25: NR | I25: NR
A26: MgSO4 | Permissive | L=1 cm | B26: MgSO4 | C26: Permissive | D26: 1 | E26: 5 | F26: 94.307832 | G26: Reachable | H26: 0.56980683 | I26: Reachable | J26: 1.1729229
A27: MgSO4 | Permissive | L=2 cm | B27: MgSO4 | C27: Permissive | D27: 2 | E27: 10 | F27: 80.082307 | G27: Reachable | H27: 2.289291 | I27: Reachable | J27: 4.7650097
A28: MgSO4 | Permissive | L=5 cm | B28: MgSO4 | C28: Permissive | D28: 5 | E28: 25 | F28: 34.422324 | G28: Reachable | H28: 14.777392 | I28: Reachable | J28: 33.871647
A29: Uric Acid | Mid-case | L=1 cm | B29: Uric Acid | C29: Mid-case | D29: 1 | E29: 5 | F29: 7.951032 | G29: Reachable | H29: 1.4819676 | I29: NR
A30: Uric Acid | Mid-case | L=2 cm | B30: Uric Acid | C30: Mid-case | D30: 2 | E30: 10 | F30: 0.31709688 | G30: NR | I30: NR
A31: Uric Acid | Mid-case | L=5 cm | B31: Uric Acid | C31: Mid-case | D31: 5 | E31: 25 | F31: 2.0018782e-05 | G31: NR | I31: NR
A32: Uric Acid | Conservative | L=1 cm | B32: Uric Acid | C32: Conservative | D32: 1 | E32: 5 | F32: 0.00010977277 | G32: NR | I32: NR
A33: Uric Acid | Conservative | L=2 cm | B33: Uric Acid | C33: Conservative | D33: 2 | E33: 10 | F33: 6.0250303e-11 | G33: NR | I33: NR
A34: Uric Acid | Conservative | L=5 cm | B34: Uric Acid | C34: Conservative | D34: 5 | E34: 25 | F34: 9.9621505e-30 | G34: NR | I34: NR
A35: Uric Acid | Permissive | L=1 cm | B35: Uric Acid | C35: Permissive | D35: 1 | E35: 5 | F35: 78.665491 | G35: Reachable | H35: 0.64009605 | I35: Reachable | J35: 1.3340205
A36: Uric Acid | Permissive | L=2 cm | B36: Uric Acid | C36: Permissive | D36: 2 | E36: 10 | F36: 44.804342 | G36: Reachable | H36: 2.6114381 | I36: Reachable | J36: 5.7545151
A37: Uric Acid | Permissive | L=5 cm | B37: Uric Acid | C37: Permissive | D37: 5 | E37: 25 | F37: 5.4394122 | G37: Reachable | H37: 19.480182 | I37: NR
A38: NXY-059 | Mid-case | L=1 cm | B38: NXY-059 | C38: Mid-case | D38: 1 | E38: 5 | F38: 99.981848 | G38: Reachable | H38: 1.6712173 | I38: Reachable | J38: 3.4277588
A39: NXY-059 | Mid-case | L=2 cm | B39: NXY-059 | C39: Mid-case | D39: 2 | E39: 10 | F39: 99.927424 | G39: Reachable | H39: 6.6856275 | I39: Reachable | J39: 13.711794
A40: NXY-059 | Mid-case | L=5 cm | B40: NXY-059 | C40: Mid-case | D40: 5 | E40: 25 | F40: 99.547833 | G40: Reachable | H40: 41.78517 | I40: Reachable | J40: 85.727146
...

Sheet d_sweep_slab
A1: Distance sweep (two-sided slab; d = centre-to-rim distance)
A3: d (mm) | B3: Equivalent core V (mL) | C3: Steady-state centre (% of boundary) | D3: Threshold M (%) | E3: Reachable?
A4: 2 | B4: =4*PI()/3*POWER(A4,3)/1000 -> 0.033510322 | C4: =100/COSH(A4/Calculator!$B$21) -> 83.513983 | D4: =Calculator!$B$11*100 -> 1 | E4: =IF(C4>=D4,"Reachable","NR") -> Reachable
A5: 4 | B5: =4*PI()/3*POWER(A5,3)/1000 -> 0.26808257 | C5: =100/COSH(A5/Calculator!$B$21) -> 53.545975 | D5: =Calculator!$B$11*100 -> 1 | E5: =IF(C5>=D5,"Reachable","NR") -> Reachable
A6: 6 | B6: =4*PI()/3*POWER(A6,3)/1000 -> 0.90477868 | C6: =100/COSH(A6/Calculator!$B$21) -> 30.534071 | D6: =Calculator!$B$11*100 -> 1 | E6: =IF(C6>=D6,"Reachable","NR") -> Reachable
A7: 8 | B7: =4*PI()/3*POWER(A7,3)/1000 -> 2.1446606 | C7: =100/COSH(A7/Calculator!$B$21) -> 16.734957 | D7: =Calculator!$B$11*100 -> 1 | E7: =IF(C7>=D7,"Reachable","NR") -> Reachable
A8: 10 | B8: =4*PI()/3*POWER(A8,3)/1000 -> 4.1887902 | C8: =100/COSH(A8/Calculator!$B$21) -> 9.0619219 | D8: =Calculator!$B$11*100 -> 1 | E8: =IF(C8>=D8,"Reachable","NR") -> Reachable
A9: 12 | B9: =4*PI()/3*POWER(A9,3)/1000 -> 7.2382295 | C9: =100/COSH(A9/Calculator!$B$21) -> 4.8895826 | D9: =Calculator!$B$11*100 -> 1 | E9: =IF(C9>=D9,"Reachable","NR") -> Reachable
A10: 14 | B10: =4*PI()/3*POWER(A10,3)/1000 -> 11.49404 | C10: =100/COSH(A10/Calculator!$B$21) -> 2.6355611 | D10: =Calculator!$B$11*100 -> 1 | E10: =IF(C10>=D10,"Reachable","NR") -> Reachable
A11: 16 | B11: =4*PI()/3*POWER(A11,3)/1000 -> 17.157285 | C11: =100/COSH(A11/Calculator!$B$21) -> 1.4201806 | D11: =Calculator!$B$11*100 -> 1 | E11: =IF(C11>=D11,"Reachable","NR") -> Reachable
A12: 18 | B12: =4*PI()/3*POWER(A12,3)/1000 -> 24.429024 | C12: =100/COSH(A12/Calculator!$B$21) -> 0.7652019 | D12: =Calculator!$B$11*100 -> 1 | E12: =IF(C12>=D12,"Reachable","NR") -> NR
A13: 20 | B13: =4*PI()/3*POWER(A13,3)/1000 -> 33.510322 | C13: =100/COSH(A13/Calculator!$B$21) -> 0.41228495 | D13: =Calculator!$B$11*100 -> 1 | E13: =IF(C13>=D13,"Reachable","NR") -> NR
A14: 22 | B14: =4*PI()/3*POWER(A14,3)/1000 -> 44.602238 | C14: =100/COSH(A14/Calculator!$B$21) -> 0.22213435 | D14: =Calculator!$B$11*100 -> 1 | E14: =IF(C14>=D14,"Reachable","NR") -> NR
A15: 24 | B15: =4*PI()/3*POWER(A15,3)/1000 -> 57.905836 | C15: =100/COSH(A15/Calculator!$B$21) -> 0.11968316 | D15: =Calculator!$B$11*100 -> 1 | E15: =IF(C15>=D15,"Reachable","NR") -> NR
... A18: 30 | B18: =4*PI()/3*POWER(A18,3)/1000 -> 113.09734 | C18: =100/COSH(A18/Calculator!$B$21) -> 0.018719058 | D18: =Calculator!$B$11*100 -> 1 | E18: =IF(C18>=D18,"Reachable","NR") -> NR

Sheet Notes
A1: Notes
A3: 1) Enter either baseline core volume V (mL) or a manual centre-to-rim distance d (mm).
A4: 2) Distance d is always the distance from the lesion rim to the lesion centre. For slab geometry, the workbook uses d directly.
A5: 3) Mid-case = D_mid and k_mid; Conservative = D_low and k_high; Permissive = D_high and k_low.
A6: 4) Reachable means the steady-state centre level Css is at or above the chosen threshold M under constant boundary exposure.
A7: 5) NR means the threshold is mathematically unattainable at steady state under the selected assumptions.
A8: 6) Standard clinical-distance times (t₁% and t₁₀%) are precomputed for the library parameter sets only. If custom D/k overrides are used, use the Python calculator for time-to-threshold.
A9: 7) This workbook is an optimistic upper-bound steady-state screen. Finite or declining systemic exposure will generally reduce centre delivery further.
